Workbook

Sheet datadasar
A1: No | B1: Jenjang | C1: Kab/Kota | D1: NPSN / NPM | E1: Nama Sekolah | F1: Alamat | G1: Jml Siswa | H1: Jml Dana 1 Tahun | I1: Sisa Dana 2025 | J1: Dana Setelah Pengurangan | K1: Pencairan (Pemotongan Bertahap) | L1: Nomor NPHD 2025 | O1: NPHD 2025 (baru) | P1: RKAS | Q1: SPJ TW4 2024 | R1: Lap. Realisasi 2025 | S1: SPTJB 2025 | T1: NPHD 2026 | U1: SK Tim 2026 | V1: Izin Operasional | W1: NPWP | X1: SK Penepatan Besaran SPP | Y1: Bank Salur | Z1: No. Rekening | AA1: atas Nama Rekening | AB1: Ket | AC1: Tanggal Penyetoran Berkas | AD1: Pengesahaan | AE1: SPJ Tahap 1 | AF1: Tanggal Penyerahan | AG1: keterangan tahap 1 | AH1: SPJ Tahap 2 | AI1: Tanggal Penyerahan | AJ1: keterangan tahap 2 | AK1: SPJ Tahap 3 | AL1: Tanggal Penyerahan | AM1: keterangan tahap 3 | AN1: Keterangan RKAS | AO1: Alasan (Jika di Tolak) | AP1: Tahap 1 | AQ1: Nilai Tahap 1 | AR1: Tahap 2 | AS1: Nilai Tahap 2 | AT1: Tahap 3 | AU1: Nilai Tahap 3 | AV1: Tahap 4 | AW1: Nilai Tahap 4 | AX1: Tahap 2 Gel 1 | AY1: Tahap 2 Gel 1 Nilai | AZ1: Tahap 2 Gel 2 | BA1: Tahap 2 Gel 2 Nilai | BB1: Tahap 2 Gel 3 | BC1: Tahap 2 Gel 3 Nilai | BD1: Tahap 2 Gel 4 | BE1: Tahap 2 Gel 4 Nilai | BF1: Tahap 2 Gel 5 | BG1: Tahap 2 Gel 5 Nilai | BH1: Tahap 2 Gel 6 | BI1: Tahap 2 Gel 6 Nilai | BJ1: Tahap 2 Gel 7 | BK1: Tahap 2 Gel 7 Nilai | BL1: Tahap 2 Gel 8 | BM1: Tahap 2 Gel 8 Nilai | BN1: Tahap 2 Gel 9 | BO1: Tahap 2 Gel 9 Nilai | BP1: Tahap 2 Gel 10 | BQ1: Tahap 2 Gel 10 Nilai | BR1: Tahap 2 Gel 11 | BS1: Tahap 2 Gel 11 Nilai | BT1: Tahap 3 Gel 1 | BU1: Tahap 3 Gel 1 Nilai | BV1: Tahap 3 Gel 2 | BW1: Tahap 3 Gel 2 Nilai | BX1: Tahap 3 Gel 3 | BY1: Tahap 3 Gel 3 Nilai | BZ1: Tahap 3 Gel 4 | CA1: Tahap 3 Gel 4 Nilai | CB1: Tahap 3 Gel 5 | CC1: Tahap 3 Gel 5 Nilai | CD1: Tahap 3 Gel 6 | CE1: Tahap 3 Gel 6 Nilai | CF1: Tahap 3 Gel 7 | CG1: Tahap 3 Gel 7 Nilai | CH1: Tahap 3 Gel 8 | CI1: Tahap 3 Gel 8 Nilai | CJ1: Tahap 4 Gel 1 | CK1: Tahap 4 Gel 1 Nilai | CL1: Tahap 4 Gel 2 | CM1: Tahap 4 Gel 2 Nilai | CN1: Tahap 4 Gel 3 | CO1: Tahap 4 Gel 3 Nilai | CP1: Tahap 4 Gel 4 | CQ1: Tahap 4 Gel 4 Nilai | CR1: Tahap 4 Gel 5 | CS1: Tahap 4 Gel 5 Nilai | CT1: Tahap 4 Gel 6 | CU1: Tahap 4 Gel 6 Nilai | CV1: Tahap 4 Gel 7 | CW1: Tahap 4 Gel 7 Nilai
A2: =SUBTOTAL(3,$B$2:B2) -> 1 | B2: MA | C2: Balikpapan | D2: 131164710001 | E2: MAN BALIKPAPAN | F2: Jl. Prapatan RT. 026 No.10 Balikpapan | G2: 552 | H2: 931776000 | L2: 000.4.3.2/ | M2: 17064 | N2: /Disdikbud-Ib | O2: TRUE | P2: TRUE | Q2: TRUE | R2: TRUE | S2: TRUE | T2: TRUE | U2: TRUE | V2: TRUE | W2: TRUE | X2: TRUE | Y2: BANKALTIMTARA | Z2: 0032251056 | AA2: MADRASAH ALIYAH NEGERI BPP | AE2: TRUE | AF2: 45875 | AH2: TRUE | AI2: 45903 | AJ2: OKE | AK2: TRUE | AL2: 45964 | AM2: OKE | AX2: TRUE | AY2: =IF(MOD(H2,4)=0,H2/4,ROUNDUP(H2/4,0)) -> 232944000 | BT2: TRUE | BU2: =IF(MOD(H2,4)=0,H2/4,ROUNDDOWN(H2/4,0)) -> 232944000 | CJ2: TRUE | CK2: =IF(MOD(H2,4)=0,H2/4,ROUNDUP(H2/4,0)) -> 232944000
A3: =SUBTOTAL(3,$B$2:B3) -> 2 | B3: MA | C3: Balikpapan | D3: 131264710001 | E3: MAS ASY-SYIFA | F3: Jl. Soekarno Hatta KM 15 Karang Joang Balikpapan Utara | G3: 226 | H3: 381488000 | L3: 000.4.3.2/ | M3: 17065 | N3: /Disdikbud-Ib | O3: TRUE | P3: TRUE | Q3: TRUE | R3: TRUE | S3: TRUE | T3: TRUE | U3: TRUE | V3: TRUE | W3: TRUE | X3: TRUE | Y3: BANKALTIMTARA | Z3: 1032027471 | AA3: MA.ASY-SYIFA | AE3: TRUE | AF3: 45904 | AG3: OKE | AH3: TRUE | AI3: 45973 | AJ3: OKE | AK3: TRUE | AL3: 46001 | AM3: Perbaikan tanggal SPTJ dan Laporan Realisasi | BB3: TRUE | BC3: =IF(MOD(H3,4)=0,H3/4,ROUNDUP(H3/4,0)) -> 95372000 | BX3: TRUE | BY3: =IF(MOD(H3,4)=0,H3/4,ROUNDDOWN(H3/4,0)) -> 95372000 | CP3: TRUE | CQ3: =IF(MOD(H3,4)=0,H3/4,ROUNDUP(H3/4,0)) -> 95372000
A4: =SUBTOTAL(3,$B$2:B4) -> 3 | B4: MA | C4: Balikpapan | D4: 131264710007 | E4: MAS DARUN NAJAH | F4: Jl. Mulawarman Gg. Mufakat RT. 31 Kel. Teritip Balikpapan Timur | G4: 21 | H4: 35448000 | L4: 000.4.3.2/ | M4: 17066 | N4: /Disdikbud-Ib | O4: TRUE | P4: TRUE | Q4: TRUE | R4: TRUE | S4: TRUE | T4: TRUE | U4: TRUE | V4: TRUE | W4: TRUE | X4: TRUE | Y4: BANKALTIMTARA | Z4: 1212044195 | AA4: YYS PDK PESANTREN DARUN NAJAH | AE4: TRUE | AF4: 45875 | AH4: TRUE | AI4: 45915 | AJ4: OKE | AK4: TRUE | AL4: 45975 | AM4: OKE | AX4: TRUE | AY4: =IF(MOD(H4,4)=0,H4/4,ROUNDUP(H4/4,0)) -> 8862000 | BT4: TRUE | BU4: =IF(MOD(H4,4)=0,H4/4,ROUNDDOWN(H4/4,0)) -> 8862000 | CJ4: TRUE | CK4: =IF(MOD(H4,4)=0,H4/4,ROUNDUP(H4/4,0)) -> 8862000
A5: =SUBTOTAL(3,$B$2:B5) -> 4 | B5: MA | C5: Balikpapan | D5: 131264710002 | E5: MAS HIDAYATUL MUSTAQIM | F5: Jl. Pasar Gunung Tembak RT. 017 Kelurahan Teritip Kecamatan Balikpapan Timur | G5: 109 | H5: 183992000 | L5: 000.4.3.2/ | M5: 17067 | N5: /Disdikbud-Ib | O5: TRUE | P5: TRUE | Q5: TRUE | R5: TRUE | S5: TRUE | T5: TRUE | U5: TRUE | V5: TRUE | W5: TRUE | X5: TRUE | Y5: BANKALTIMTARA | Z5: 0032268731 | AA5: MA HIDAYATUL MUSTAQIM BPP | AE5: TRUE | AF5: 45875 | AH5: TRUE | AI5: 45915 | AJ5: Tanggal Surat Pernyatan salah | AK5: TRUE | AL5: 45973 | AM5: OKE | AX5: TRUE | AY5: =IF(MOD(H5,4)=0,H5/4,ROUNDUP(H5/4,0)) -> 45998000 | BT5: TRUE | BU5: =IF(MOD(H5,4)=0,H5/4,ROUNDDOWN(H5/4,0)) -> 45998000 | CJ5: TRUE | CK5: =IF(MOD(H5,4)=0,H5/4,ROUNDUP(H5/4,0)) -> 45998000
A6: =SUBTOTAL(3,$B$2:B6) -> 5 | B6: MA | C6: Balikpapan | D6: 131264710006 | E6: MAS MARDHATILLAH | F6: Jl. Padat Karya 1 No. 250 RT. 068, Kel. Graha Indah, kec. Balikpapan Utara KALTIM | G6: 36 | H6: 60768000 | L6: 000.4.3.2/ | M6: 17068 | N6: /Disdikbud-Ib | O6: TRUE | P6: TRUE | Q6: TRUE | R6: TRUE | S6: TRUE | T6: TRUE | U6: TRUE | V6: TRUE | W6: TRUE | X6: TRUE | Y6: BANKALTIMTARA | Z6: 0032426085 | AA6: MADRASAH ALIYAH MARDHATILAH | AE6: TRUE | AF6: 45875 | AH6: TRUE | AI6: 45973 | AJ6: Perbaikan Tgl Lap Realisasi, SPTJ, Surat Kesanggupan | AK6: TRUE | AL6: 46001 | AM6: Perbaikan tanggal surat kesanggupan | AX6: TRUE | AY6: =IF(MOD(H6,4)=0,H6/4,ROUNDUP(H6/4,0)) -> 15192000 | BX6: TRUE | BY6: =IF(MOD(H6,4)=0,H6/4,ROUNDDOWN(H6/4,0)) -> 15192000 | CP6: TRUE | CQ6: =IF(MOD(H6,4)=0,H6/4,ROUNDUP(H6/4,0)) -> 15192000
A7: =SUBTOTAL(3,$B$2:B7) -> 6 | B7: MA | C7: Balikpapan | D7: 131264710003 | E7: MAS RAADHIYATAN MARDHIYYAH PUTRI | F7: Jl. Mulawarman RT. 026, kelurahan teritip, kecamatan balikpapan Timur. | G7: 165 | H7: 278520000 | L7: 000.4.3.2/ | M7: 17069 | N7: /Disdikbud-Ib | O7: TRUE | P7: TRUE | Q7: TRUE | R7: TRUE | S7: TRUE | T7: TRUE | U7: TRUE | V7: TRUE | W7: TRUE | X7: TRUE | Y7: BANKALTIMTARA | Z7: 1212117681 | AA7: MA RAADHIYATAN MARDHIYYAH PUTR | AE7: TRUE | AF7: 45875 | AH7: TRUE | AI7: 45915 | AK7: TRUE | AL7: 45973 | AM7: OKE | AX7: TRUE | AY7: =IF(MOD(H7,4)=0,H7/4,ROUNDUP(H7/4,0)) -> 69630000 | BT7: TRUE | BU7: =IF(MOD(H7,4)=0,H7/4,ROUNDDOWN(H7/4,0)) -> 69630000 | CJ7: TRUE | CK7: =IF(MOD(H7,4)=0,H7/4,ROUNDUP(H7/4,0)) -> 69630000
A8: =SUBTOTAL(3,$B$2:B8) -> 7 | B8: SMA | C8: Balikpapan | D8: 30401501 | E8: SMAS KARTIKA V-1 | F8: JL. TANJUNG PURA 1 BALIKPAPAN | G8: 456 | H8: 745788000 | L8: 000.4.3.2/ | M8: 17086 | N8: /Disdikbud-Ib | O8: TRUE | P8: TRUE | Q8: TRUE | R8: TRUE | S8: TRUE | T8: TRUE | U8: TRUE | V8: TRUE | W8: TRUE | X8: TRUE | Y8: BANKALTIMTARA | Z8: 0032423949 | AA8: SMU KARTIKA V-1 BALIKPAPAN | AE8: TRUE | AF8: 45880 | AH8: TRUE | AI8: 45945 | AJ8: Laporan Kegiatan | AK8: TRUE | AL8: 46008 | AM8: OKE | AX8: TRUE | AY8: =IF(MOD(H8,4)=0,H8/4,ROUNDUP(H8/4,0)) -> 186447000 | BV8: TRUE | BW8: =IF(MOD(H8,4)=0,H8/4,ROUNDDOWN(H8/4,0)) -> 186447000 | CR8: TRUE | CS8: =IF(MOD(H8,4)=0,H8/4,ROUNDUP(H8/4,0)) -> 186447000
A9: =SUBTOTAL(3,$B$2:B9) -> 8 | B9: MA | C9: Balikpapan | D9: 131264710004 | E9: MAS RADHIYATAN MARDHIYYAH PUTRA | F9: Jl. Mulawarman RT. 025, kelurahan teritip, kecamatan balikpapan Timur. | G9: 117 | H9: 197496000 | L9: 000.4.3.2/ | M9: 17070 | N9: /Disdikbud-Ib | O9: TRUE | P9: TRUE | Q9: TRUE | R9: TRUE | S9: TRUE | T9: TRUE | U9: TRUE | V9: TRUE | W9: TRUE | X9: TRUE | Y9: BANKALTIMTARA | Z9: 0032250718 | AA9: MA RAADHIYATAN MARDHIYYAH PUTR | AE9: TRUE | AF9: 45875 | AH9: TRUE | AI9: 45915 | AJ9: OKE | AK9: TRUE | AL9: 45973 | AM9: Oke | AX9: TRUE | AY9: =IF(MOD(H9,4)=0,H9/4,ROUNDUP(H9/4,0)) -> 49374000 | BT9: TRUE | BU9: =IF(MOD(H9,4)=0,H9/4,ROUNDDOWN(H9/4,0)) -> 49374000 | CJ9: TRUE | CK9: =IF(MOD(H9,4)=0,H9/4,ROUNDUP(H9/4,0)) -> 49374000
A10: =SUBTOTAL(3,$B$2:B10) -> 9 | B10: MA | C10: Balikpapan | D10: 131264710005 | E10: MAS SABILAL MUHTADIN | F10: Jl. P.Antasari RT. 062 No. 51, Kelurahan Karang Rejo Balikpapan | G10: 33 | H10: 55704000 | L10: 000.4.3.2/ | M10: 17071 | N10: /Disdikbud-Ib | O10: TRUE | P10: TRUE | Q10: TRUE | R10: FALSE | S10: TRUE | T10: TRUE | U10: TRUE | V10: TRUE | W10: TRUE | X10: TRUE | Y10: BANKALTIMTARA | Z10: 0032597289 | AA10: MA SABILAL MUHTADIN BALIKPAPAN | AE10: TRUE | AF10: 45875 | AH10: TRUE | AI10: 45915 | AJ10: OKE | AK10: TRUE | AL10: 45973 | AM10: OKE | AX10: TRUE | AY10: =IF(MOD(H10,4)=0,H10/4,ROUNDUP(H10/4,0)) -> 13926000 | BT10: TRUE | BU10: =IF(MOD(H10,4)=0,H10/4,ROUNDDOWN(H10/4,0)) -> 13926000 | CJ10: TRUE | CK10: =IF(MOD(H10,4)=0,H10/4,ROUNDUP(H10/4,0)) -> 13926000
A11: =SUBTOTAL(3,$B$2:B11) -> 10 | B11: SLB | C11: Balikpapan | D11: 69965143 | E11: Sekolah Khusus Santo Fransiskus Assisi | F11: Jalan. Mayor (Pol) Zaenal Arifin No. 40 Rt. 18 Dam | G11: 81 | H11: 160825500 | L11: 000.4.3.2/ | M11: 17072 | N11: /Disdikbud-Ib | O11: TRUE | P11: TRUE | Q11: TRUE | R11: TRUE | S11: TRUE | T11: TRUE | U11: TRUE | V11: TRUE | W11: TRUE | X11: TRUE | Y11: BANKALTIMTARA | Z11: 0031576245 | AA11: 69965143 SKH ST FRANSISKUS A | AE11: TRUE | AF11: 45875 | AG11: Perbaikan (SPTJ belum ada saldo awal) | AH11: TRUE | AI11: 45943 | AJ11: Rekening koran tidak lengkap, sptjb tidak ada saldo awal | AK11: TRUE | AL11: 45996 | AM11: Perbaikan (SPTJ belum ada saldo awal) | AX11: TRUE | AY11: =IF(MOD(H11,4)=0,H11/4,ROUNDUP(H11/4,0)) -> 40206375 | BV11: TRUE | BW11: =IF(MOD(H11,4)=0,H11/4,ROUNDDOWN(H11/4,0)) -> 40206375 | CP11: TRUE | CQ11: =IF(MOD(H11,4)=0,H11/4,ROUNDUP(H11/4,0)) -> 40206375
A12: =SUBTOTAL(3,$B$2:B12) -> 11 | B12: SLB | C12: Balikpapan | D12: 30402882 | E12: SLB DHARMA KENCANA BALIKPAPAN | F12: Jl. Pembangunan No.30 Blok A | G12: 130 | H12: 258115000 | L12: 000.4.3.2/ | M12: 17073 | N12: /Disdikbud-Ib | O12: TRUE | P12: TRUE | Q12: TRUE | R12: TRUE | S12: TRUE | T12: TRUE | U12: TRUE | V12: TRUE | W12: TRUE | X12: TRUE | Y12: BANKALTIMTARA | Z12: 0032309364 | AA12: SLB DHARMA KENCANA | AE12: TRUE | AF12: 45882 | AH12: TRUE | AI12: 45915 | AJ12: Tanggal Kata Pengantar dan tgl sptjb dan Lap Realisasi | AK12: TRUE | AL12: 45993 | AM12: OKE | AX12: TRUE | AY12: =IF(MOD(H12,4)=0,H12/4,ROUNDUP(H12/4,0)) -> 64528750 | BT12: TRUE | BU12: =IF(MOD(H12,4)=0,H12/4,ROUNDDOWN(H12/4,0)) -> 64528750 | CN12: TRUE | CO12: =IF(MOD(H12,4)=0,H12/4,ROUNDUP(H12/4,0)) -> 64528750
A13: =SUBTOTAL(3,$B$2:B13) -> 12 | B13: SLB | C13: Balikpapan | D13: 30402883 | E13: SLB TUNAS BANGSA | F13: Jl. Kutilang Rss Damai Iii Rt. 28 | G13: 84 | H13: 166782000 | L13: 000.4.3.2/ | M13: 17074 | N13: /Disdikbud-Ib | O13: TRUE | P13: TRUE | Q13: TRUE | R13: TRUE | S13: TRUE | T13: TRUE | U13: TRUE | V13: TRUE | W13: TRUE | X13: FALSE | Y13: BANKALTIMTARA | Z13: 1022021202 | AA13: SLB TUNAS BANGSA | AE13: TRUE | AF13: 45897 | AG13: OKE | AH13: TRUE | AI13: 45922 | AJ13: OKE | AK13: TRUE | AL13: 45979 | AM13: OKE | AZ13: TRUE | BA13: =IF(MOD(H13,4)=0,H13/4,ROUNDUP(H13/4,0)) -> 41695500 | BT13: TRUE | BU13: =IF(MOD(H13,4)=0,H13/4,ROUNDDOWN(H13/4,0)) -> 41695500 | CJ13: TRUE | CK13: =IF(MOD(H13,4)=0,H13/4,ROUNDUP(H13/4,0)) -> 41695500
A14: =SUBTOTAL(3,$B$2:B14) -> 13 | B14: SMA | C14: Balikpapan | D14: 70048473 | E14: SMA AL IMAM ISLAMIC SCHOOL BALIKPAPAN | F14: JL. BUKIT CINTA DAMAI | G14: 24 | H14: 39252000 | L14: 000.4.3.2/ | M14: 17075 | N14: /Disdikbud-Ib | O14: TRUE | P14: TRUE | Q14: TRUE | R14: TRUE | S14: TRUE | T14: TRUE | U14: TRUE | V14: TRUE | W14: TRUE | X14: TRUE | Y14: BANKALTIMTARA | Z14: 0032943012 | AA14: SMA AL IMAN ISLAMIC SCHOOL BPP | AD14: Sekolah Baru | AE14: TRUE | AF14: 45876 | AH14: TRUE | AI14: 45931 | AK14: TRUE | AL14: 45967 | AM14: OKE | AX14: TRUE | AY14: =IF(MOD(H14,4)=0,H14/4,ROUNDUP(H14/4,0)) -> 9813000 | BT14: TRUE | BU14: =IF(MOD(H14,4)=0,H14/4,ROUNDDOWN(H14/4,0)) -> 9813000 | CJ14: TRUE | CK14: =IF(MOD(H14,4)=0,H14/4,ROUNDUP(H14/4,0)) -> 9813000
A15: =SUBTOTAL(3,$B$2:B15) -> 14 | B15: SMA | C15: Balikpapan | D15: 69987671 | E15: SMA INTEGRAL LUQMAN AL HAKIM | F15: Jl. Perjuangan No.72 RT 06 | G15: 56 | H15: 91588000 | L15: 000.4.3.2/ | M15: 17076 | N15: /Disdikbud-Ib | O15: TRUE | P15: TRUE | Q15: FALSE | R15: TRUE | S15: TRUE | T15: TRUE | U15: TRUE | V15: TRUE | W15: FALSE | X15: TRUE | Y15: BANKALTIMTARA | Z15: 5000459283 | AA15: SMA INTEGRAL LUQMAN AL HAKIM BALIKPAPAN | AE15: FALSE | AH15: FALSE | AK15: FALSE
A16: =SUBTOTAL(3,$B$2:B16) -> 15 | B16: SMA | C16: Balikpapan | D16: 69901305 | E16: SMA IT AL AULIYA | F16: MT. HARYONO RT. 43 | G16: 222 | H16: 363081000 | L16: 000.4.3.2/ | M16: 17077 | N16: /Disdikbud-Ib | O16: TRUE | P16: TRUE | Q16: TRUE | R16: TRUE | S16: TRUE | T16: TRUE | U16: TRUE | V16: TRUE | W16: TRUE | X16: TRUE | Y16: BNI | Z16: 0436832875 | AA16: SMA IT AL AULIYA BALIKPAPAN | AE16: TRUE | AF16: 45876 | AG16: Laporan Realisasi Perbaikan | AH16: TRUE | AI16: 45931 | AK16: TRUE | AL16: 45967 | AM16: OKE | AX16: TRUE | AY16: =IF(MOD(H16,4)=0,H16/4,ROUNDUP(H16/4,0)) -> 90770250 | BT16: TRUE | BU16: =IF(MOD(H16,4)=0,H16/4,ROUNDDOWN(H16/4,0)) -> 90770250 | CJ16: TRUE | CK16: =IF(MOD(H16,4)=0,H16/4,ROUNDUP(H16/4,0)) -> 90770250
A17: =SUBTOTAL(3,$B$2:B17) -> 16 | B17: SMA | C17: Balikpapan | D17: 70046800 | E17: SMA IT AL AZHAR BOARDING SCHOOL | F17: Jl. Mulawarman RT.041 | G17: 23 | H17: 37616500 | L17: 000.4.3.2/ | M17: 17078 | N17: /Disdikbud-Ib | O17: TRUE | P17: TRUE | Q17: FALSE | R17: FALSE | S17: FALSE | T17: TRUE | U17: TRUE | V17: TRUE | W17: TRUE | X17: TRUE | Y17: BANKALTIMTARA | Z17: 5000459362 | AA17: SMA IT AL AZHAR BOARDING SCHOOL | AD17: Sekolah Baru | AE17: TRUE | AF17: 45876 | AG17: OKE | AH17: TRUE | AI17: 45931 | AK17: TRUE | AL17: 45967 | AM17: OKE | AX17: TRUE | AY17: =IF(MOD(H17,4)=0,H17/4,ROUNDUP(H17/4,0)) -> 9404125 | BT17: TRUE | BU17: =IF(MOD(H17,4)=0,H17/4,ROUNDDOWN(H17/4,0)) -> 9404125 | CJ17: TRUE | CK17: =IF(MOD(H17,4)=0,H17/4,ROUNDUP(H17/4,0)) -> 9404125
A18: =SUBTOTAL(3,$B$2:B18) -> 17 | B18: SMA | C18: Balikpapan | D18: 69974737 | E18: SMA KRISTEN HARAPAN BANGSA | F18: JL. INDRAKILA RT 04 NO 99 G | G18: 99 | H18: 161914500 | L18: 000.4.3.2/ | M18: 17079 | N18: /Disdikbud-Ib | O18: TRUE | P18: TRUE | Q18: TRUE | R18: TRUE | S18: TRUE | T18: TRUE | U18: TRUE | V18: TRUE | W18: TRUE | X18: TRUE | Y18: BANKALTIMTARA | Z18: 0034212741 | AA18: SMA KRISTEN HARAPAN BANGSA | AE18: TRUE | AF18: 45894 | AG18: OKE | AH18: TRUE | AI18: 45931 | AK18: TRUE | AL18: 45967 | AM18: OKE | AZ18: TRUE | BA18: =IF(MOD(H18,4)=0,H18/4,ROUNDUP(H18/4,0)) -> 40478625 | BT18: TRUE | BU18: =IF(MOD(H18,4)=0,H18/4,ROUNDDOWN(H18/4,0)) -> 40478625 | CJ18: TRUE | CK18: =IF(MOD(H18,4)=0,H18/4,ROUNDUP(H18/4,0)) -> 40478625
A19: =SUBTOTAL(3,$B$2:B19) -> 18 | B19: SMA | C19: Balikpapan | D19: 30401498 | E19: SMA MUHAMMADIYAH 2 AL-MUJAHIDIN | F19: JL. SOEKARNO HATTA KM. 10 | G19: 374 | H19: 611677000 | L19: 000.4.3.2/ | M19: 17080 | N19: /Disdikbud-Ib | O19: TRUE | P19: TRUE | Q19: TRUE | R19: TRUE | S19: TRUE | T19: TRUE | U19: TRUE | V19: TRUE | W19: TRUE | X19: TRUE | Y19: BANKALTIMTARA | Z19: 0032252320 | AA19: SMA MUHAMMADIYAH 2 BALIKPAPAN | AE19: TRUE | AF19: 45876 | AH19: TRUE | AI19: 45931 | AK19: TRUE | AL19: 45967 | AM19: OKE | AX19: TRUE | AY19: =IF(MOD(H19,4)=0,H19/4,ROUNDUP(H19/4,0)) -> 152919250 | BT19: TRUE | BU19: =IF(MOD(H19,4)=0,H19/4,ROUNDDOWN(H19/4,0)) -> 152919250 | CJ19: TRUE | CK19: =IF(MOD(H19,4)=0,H19/4,ROUNDUP(H19/4,0)) -> 152919250
A20: =SUBTOTAL(3,$B$2:B20) -> 19 | B20: SMA | C20: Balikpapan | D20: 70028641 | E20: SMA NASIONAL KPS | F20: Jl. Sport No.1 RT.19 | G20: 174 | H20: 284577000 | L20: 000.4.3.2/ | M20: 17081 | N20: /Disdikbud-Ib | O20: TRUE | P20: TRUE | Q20: TRUE | R20: TRUE | S20: TRUE | T20: TRUE | U20: TRUE | V20: TRUE | W20: TRUE | X20: TRUE | Y20: BANKALTIMTARA | Z20: 0031476518 | AA20: SMA NASIONAL KPS | AE20: TRUE | AF20: 45894 | AG20: OKE | AH20: TRUE | AI20: 45931 | AK20: TRUE | AL20: 45967 | AM20: OKE | AZ20: TRUE | BA20: =IF(MOD(H20,4)=0,H20/4,ROUNDUP(H20/4,0)) -> 71144250 | BT20: TRUE | BU20: =IF(MOD(H20,4)=0,H20/4,ROUNDDOWN(H20/4,0)) -> 71144250 | CJ20: TRUE | CK20: =IF(MOD(H20,4)=0,H20/4,ROUNDUP(H20/4,0)) -> 71144250
A21: =SUBTOTAL(3,$B$2:B21) -> 20 | B21: SMA | C21: Balikpapan | D21: 70010866 | E21: SMAIT Istiqamah Balikpapan | F21: Jl. Kol. H. Syarifuddin Yoes No 1 RT 41 | G21: 145 | H21: 237147500 | L21: 000.4.3.2/ | M21: 17082 | N21: /Disdikbud-Ib | O21: TRUE | P21: TRUE | Q21: TRUE | R21: TRUE | S21: TRUE | T21: TRUE | U21: TRUE | V21: TRUE | W21: TRUE | X21: TRUE | Y21: BANKALTIMTARA | Z21: 1671501477 | AA21: 70010866 SMAIT ISTIQAMAH BPP | AE21: TRUE | AF21: 45876 | AH21: TRUE | AI21: 45931 | AK21: TRUE | AL21: 45967 | AM21: OKE | AX21: TRUE | AY21: =IF(MOD(H21,4)=0,H21/4,ROUNDUP(H21/4,0)) -> 59286875 | BT21: TRUE | BU21: =IF(MOD(H21,4)=0,H21/4,ROUNDDOWN(H21/4,0)) -> 59286875 | CJ21: TRUE | CK21: =IF(MOD(H21,4)=0,H21/4,ROUNDUP(H21/4,0)) -> 59286875
A22: =SUBTOTAL(3,$B$2:B22) -> 21 | B22: SMA | C22: Balikpapan | D22: 69974739 | E22: SMAIT TRI SUKSES GENERUS | F22: Jl. Guntur Damai, RT. 38 | G22: 129 | H22: 210979500 | L22: 000.4.3.2/ | M22: 17083 | N22: /Disdikbud-Ib | O22: TRUE | P22: TRUE | Q22: TRUE | R22: TRUE | S22: TRUE | T22: TRUE | U22: TRUE | V22: TRUE | W22: TRUE | X22: TRUE | Y22: BANKALTIMTARA | Z22: 0032564364 | AA22: SMAIT TRI SUKSES GENERUS | AE22: TRUE | AF22: 45876 | AG22: OKE | AH22: TRUE | AI22: 45931 | AK22: TRUE | AL22: 45967 | AM22: OKE | AX22: TRUE | AY22: =IF(MOD(H22,4)=0,H22/4,ROUNDUP(H22/4,0)) -> 52744875 | BT22: TRUE | BU22: =IF(MOD(H22,4)=0,H22/4,ROUNDDOWN(H22/4,0)) -> 52744875 | CJ22: TRUE | CK22: =IF(MOD(H22,4)=0,H22/4,ROUNDUP(H22/4,0)) -> 52744875
A23: =SUBTOTAL(3,$B$2:B23) -> 22 | B23: SMA | C23: Balikpapan | D23: 30401409 | E23: SMAS ADVENT | F23: JL. KAPTEN PIERE TENDEAN NO.57 | G23: 91 | H23: 148830500 | L23: 000.4.3.2/ | M23: 17084 | N23: /Disdikbud-Ib | O23: TRUE | P23: TRUE | Q23: TRUE | R23: TRUE | S23: TRUE | T23: TRUE | U23: TRUE | V23: TRUE | W23: TRUE | X23: TRUE | Y23: BANKALTIMTARA | Z23: 0031576237 | AA23: 30401409 SMAS ADVENT | AE23: TRUE | AF23: 45876 | AH23: TRUE | AI23: 45931 | AK23: TRUE | AL23: 45967 | AM23: OKE | AX23: TRUE | AY23: =IF(MOD(H23,4)=0,H23/4,ROUNDUP(H23/4,0)) -> 37207625 | BT23: TRUE | BU23: =IF(MOD(H23,4)=0,H23/4,ROUNDDOWN(H23/4,0)) -> 37207625 | CJ23: TRUE | CK23: =IF(MOD(H23,4)=0,H23/4,ROUNDUP(H23/4,0)) -> 37207625
A24: =SUBTOTAL(3,$B$2:B24) -> 23 | B24: SMA | C24: Balikpapan | D24: 30402919 | E24: SMAS AL HASSAN | F24: JL. TELAGA SARI KOMPLEK PELAJAR | G24: 67 | H24: 109578500 | L24: 000.4.3.2/ | M24: 17085 | N24: /Disdikbud-Ib | O24: TRUE | P24: TRUE | Q24: TRUE | R24: TRUE | S24: TRUE | T24: TRUE | U24: TRUE | V24: TRUE | W24: TRUE | X24: TRUE | Y24: BANKALTIMTARA | Z24: 0032459480 | AA24: SMA AL-HASSAN BALIKPAPAN | AE24: TRUE | AF24: 45876 | AH24: TRUE | AI24: 45931 | AK24: TRUE | AL24: 45967 | AM24: OKE | AX24: TRUE | AY24: =IF(MOD(H24,4)=0,H24/4,ROUNDUP(H24/4,0)) -> 27394625 | BT24: TRUE | BU24: =IF(MOD(H24,4)=0,H24/4,ROUNDDOWN(H24/4,0)) -> 27394625 | CJ24: TRUE | CK24: =IF(MOD(H24,4)=0,H24/4,ROUNDUP(H24/4,0)) -> 27394625
A25: =SUBTOTAL(3,$B$2:B25) -> 24 | B25: SMA | C25: Balikpapan | D25: 30401500 | E25: SMAS KATHOLIK ADI SUCIPTO | F25: JL. MT HARYONO RT. 42 | G25: 173 | H25: 282941500 | L25: 000.4.3.2/ | M25: 17087 | N25: /Disdikbud-Ib | O25: TRUE | P25: TRUE | Q25: TRUE | R25: TRUE | S25: TRUE | T25: TRUE | U25: TRUE | V25: TRUE | W25: TRUE | X25: TRUE | Y25: BANKALTIMTARA | Z25: 0031576253 | AA25: 30401500 SMAS KATHOLIK ADI S | AE25: TRUE | AF25: 45904 | AG25: Tanggal SUrat Pernyataan | AH25: TRUE | AI25: 45943 | AJ25: Perbaikan tanggal surat pernyataan, | AK25: TRUE | AL25: 45996 | AM25: Perbaikan tanggal SPTJB dan Lap Realisasi | BB25: TRUE | BC25: =IF(MOD(H25,4)=0,H25/4,ROUNDUP(H25/4,0)) -> 70735375 | BV25: TRUE | BW25: =IF(MOD(H25,4)=0,H25/4,ROUNDDOWN(H25/4,0)) -> 70735375 | CP25: TRUE | CQ25: =IF(MOD(H25,4)=0,H25/4,ROUNDUP(H25/4,0)) -> 70735375
A26: =SUBTOTAL(3,$B$2:B26) -> 25 | B26: SMA | C26: Balikpapan | D26: 30401499 | E26: SMAS MUHAMMADIYAH 1 | F26: JL. LETJEND S. PARMAN RT 24 NO.19 | G26: 56 | H26: 91588000 | L26: 000.4.3.2/ | M26: 17088 | N26: /Disdikbud-Ib | O26: TRUE | P26: TRUE | Q26: TRUE | R26: TRUE | S26: TRUE | T26: TRUE | U26: TRUE | V26: TRUE | W26: TRUE | X26: TRUE | Y26: BNI | Z26: 0298531779 | AA26: SMAS MUHAMMADIYAH 1 | AE26: TRUE | AF26: 45876 | AH26: TRUE | AI26: 45931 | AK26: TRUE | AL26: 45973 | AM26: OKE | AX26: TRUE | AY26: =IF(MOD(H26,4)=0,H26/4,ROUNDUP(H26/4,0)) -> 22897000 | BT26: TRUE | BU26: =IF(MOD(H26,4)=0,H26/4,ROUNDDOWN(H26/4,0)) -> 22897000 | CJ26: TRUE | CK26: =IF(MOD(H26,4)=0,H26/4,ROUNDUP(H26/4,0)) -> 22897000
A27: =SUBTOTAL(3,$B$2:B27) -> 26 | B27: SMA | C27: Balikpapan | D27: 30401497 | E27: SMAS NUSANTARA | F27: JL. Gunung Samarinda IV No. 34 RT. 42 Balikpapan U | G27: 220 | H27: 359810000 | L27: 000.4.3.2/ | M27: 17089 | N27: /Disdikbud-Ib | O27: TRUE | P27: TRUE | Q27: TRUE | R27: TRUE | S27: TRUE | T27: TRUE | U27: TRUE | V27: TRUE | W27: TRUE | X27: TRUE | Y27: BANKALTIMTARA | Z27: 0032251285 | AA27: SMA NUSANTARA BALIKPAPAN | AE27: TRUE | AF27: 45876 | AH27: TRUE | AI27: 45931 | AK27: TRUE | AL27: 45967 | AM27: OKE | AX27: TRUE | AY27: =IF(MOD(H27,4)=0,H27/4,ROUNDUP(H27/4,0)) -> 89952500 | BT27: TRUE | BU27: =IF(MOD(H27,4)=0,H27/4,ROUNDDOWN(H27/4,0)) -> 89952500 | CJ27: TRUE | CK27: =IF(MOD(H27,4)=0,H27/4,ROUNDUP(H27/4,0)) -> 89952500
A28: =SUBTOTAL(3,$B$2:B28) -> 27 | B28: SMA | C28: Balikpapan | D28: 30401496 | E28: SMAS PATRA DHARMA | F28: JL. WARUKIN III PANORAMA | G28: 452 | H28: 739246000 | L28: 000.4.3.2/ | M28: 17090 | N28: /Disdikbud-Ib | O28: TRUE | P28: TRUE | Q28: TRUE | R28: TRUE | S28: TRUE | T28: TRUE | U28: TRUE | V28: TRUE | W28: TRUE | X28: TRUE | Y28: BNI | Z28: 0297211864 | AA28: SMA PATRA DHARMA | AE28: TRUE | AF28: 45894 | AG28: Perbaikan Laporan Realisasi dan SPTJM | AH28: TRUE | AI28: 45931 | AK28: TRUE | AL28: 45973 | AM28: OKE | AZ28: TRUE | BA28: =IF(MOD(H28,4)=0,H28/4,ROUNDUP(H28/4,0)) -> 184811500 | BT28: TRUE | BU28: =IF(MOD(H28,4)=0,H28/4,ROUNDDOWN(H28/4,0)) -> 184811500 | CJ28: TRUE | CK28: =IF(MOD(H28,4)=0,H28/4,ROUNDUP(H28/4,0)) -> 184811500
A29: =SUBTOTAL(3,$B$2:B29) -> 28 | B29: SMA | C29: Balikpapan | D29: 30401493 | E29: SMAS SYAICHONA CHOLIL | F29: JL. MULAWARMAN RT 10 NO.59 | G29: 117 | H29: 191353500 | L29: 000.4.3.2/ | M29: 17091 | N29: /Disdikbud-Ib | O29: TRUE | P29: TRUE | Q29: TRUE | R29: TRUE | S29: TRUE | T29: TRUE | U29: FALSE | V29: TRUE | W29: TRUE | X29: TRUE | Y29: BANKALTIMTARA | Z29: 0032333231 | AA29: SMA SYAICHONA CHOLIL | AE29: TRUE | AF29: 45876 | AH29: TRUE | AI29: 45931 | AK29: TRUE | AL29: 45967 | AM29: OKE | AX29: TRUE | AY29: =IF(MOD(H29,4)=0,H29/4,ROUNDUP(H29/4,0)) -> 47838375 | BT29: TRUE | BU29: =IF(MOD(H29,4)=0,H29/4,ROUNDDOWN(H29/4,0)) -> 47838375 | CJ29: TRUE | CK29: =IF(MOD(H29,4)=0,H29/4,ROUNDUP(H29/4,0)) -> 47838375
A30: =SUBTOTAL(3,$B$2:B30) -> 29 | B30: SMK | C30: Balikpapan | D30: 69869763 | E30: SMK BHAKTI INDONESIA | F30: Jl. Pattimura No 25 RT 28 Perumahan Sosial | G30: 8 | H30: 15662000 | L30: 000.4.3.2/ | M30: 17092 | N30: /Disdikbud-Ib | O30: TRUE | P30: TRUE | Q30: TRUE | R30: TRUE | S30: TRUE | T30: TRUE | U30: TRUE | V30: TRUE | W30: TRUE | X30: TRUE | Y30: BANKALTIMTARA | Z30: 0031476411 | AA30: SMK BHAKTI INDONESIA | AE30: TRUE | AF30: 45870 | AH30: TRUE | AI30: 45938 | AJ30: OKE | AK30: TRUE | AL30: 45978 | AM30: OKE | AX30: TRUE | AY30: =IF(MOD(H30,4)=0,H30/4,ROUNDUP(H30/4,0)) -> 3915500 | BT30: TRUE | BU30: =IF(MOD(H30,4)=0,H30/4,ROUNDDOWN(H30/4,0)) -> 3915500 | CJ30: TRUE | CK30: =IF(MOD(H30,4)=0,H30/4,ROUNDUP(H30/4,0)) -> 3915500
A31: =SUBTOTAL(3,$B$2:B31) -> 30 | B31: SMK | C31: Balikpapan | D31: 69894554 | E31: SMK BINA PRESTASI AMI BALIKPAPAN | F31: Telindung Jl Masjid Al-Kahfi RT 86 | G31: 267 | H31: 522719250 | L31: 000.4.3.2/ | M31: 17093 | N31: /Disdikbud-Ib | O31: TRUE | P31: TRUE | Q31: TRUE | R31: TRUE | S31: TRUE | T31: TRUE | U31: TRUE | V31: TRUE | W31: TRUE | X31: TRUE | Y31: BANKALTIMTARA | Z31: 0031476097 | AA31: SMK BINA PRESTASI AMI BPP | AE31: TRUE | AF31: 45870 | AH31: TRUE | AI31: 45938 | AJ31: OKE | AK31: TRUE | AL31: 45978 | AM31: OKE | AX31: TRUE | AY31: =IF(MOD(H31,4)=0,H31/4,ROUNDUP(H31/4,0)) -> 130679813 | BT31: TRUE | BU31: =IF(MOD(H31,4)=0,H31/4,ROUNDDOWN(H31/4,0)) -> 130679812 | CJ31: TRUE | CK31: =IF(MOD(H31,4)=0,H31/4,ROUNDUP(H31/4,0)) -> 130679813
A32: =SUBTOTAL(3,$B$2:B32) -> 31 | B32: SMK | C32: Balikpapan | D32: 70040456 | E32: SMK CENDEKIA AL-IZZAH | F32: JL SEI WAIN KM 15 RT 033 | G32: 30 | H32: 58732500 | L32: 000.4.3.2/ | M32: 17094 | N32: /Disdikbud-Ib | O32: TRUE | P32: TRUE | Q32: TRUE | R32: FALSE | S32: FALSE | T32: TRUE | U32: TRUE | V32: TRUE | W32: TRUE | X32: TRUE | Y32: BANKALTIMTARA | Z32: 0034234256 | AA32: SMK CENDEKIA AL IZZAH | AE32: TRUE | AF32: 45916 | AG32: Laporan Kegiatan, Lap Realisasi tidak ada, Perbaikan SPTJB | AH32: TRUE | AI32: 45979 | AJ32: Laporan Kegiatan, Lap Realisasi tidak ada, Perbaikan SPTJB | AK32: TRUE | AL32: 46020 | AM32: Perbaikan (proses) | BB32: TRUE | BC32: =IF(MOD(H32,4)=0,H32/4,ROUNDUP(H32/4,0)) -> 14683125 | BX32: TRUE | BY32: =IF(MOD(H32,4)=0,H32/4,ROUNDDOWN(H32/4,0)) -> 14683125 | CT32: TRUE | CU32: =IF(MOD(H32,4)=0,H32/4,ROUNDUP(H32/4,0)) -> 14683125
A33: =SUBTOTAL(3,$B$2:B33) -> 32 | B33: SMK | C33: Balikpapan | D33: 69982415 | E33: SMK MIGAS INSAN KAMIL BALIKPAPAN | F33: Jl. Ksatrian KM.8 RT.38 Kel. Graha Indah Balikpapa | G33: 278 | H33: 544254500 | L33: 000.4.3.2/ | M33: 17095 | N33: /Disdikbud-Ib | O33: TRUE | P33: FALSE | Q33: TRUE | R33: FALSE | S33: FALSE | T33: FALSE | U33: TRUE | V33: TRUE | W33: TRUE | X33: FALSE | Y33: BANKALTIMTARA | Z33: 0031476232 | AA33: SMK MIGAS INSAN KAMIL | AE33: FALSE | AH33: FALSE | AK33: FALSE
A34: =SUBTOTAL(3,$B$2:B34) -> 33 | B34: SMK | C34: Balikpapan | D34: 69939919 | E34: SMK NURUL KHAERAT LIL MUHIBBIN | F34: JL. SEPINGGAN BARU RT. 17 | G34: 8 | H34: 15662000 | L34: 000.4.3.2/ | M34: 17096 | N34: /Disdikbud-Ib | O34: TRUE | P34: FALSE | Q34: FALSE | R34: TRUE | S34: TRUE | T34: TRUE | U34: TRUE | V34: TRUE | W34: TRUE | X34: FALSE | Y34: BANKALTIMTARA | Z34: 0031476356 | AA34: SMK NURUL KHAEERAT LILMUHIBBIN | AE34: FALSE | AH34: FALSE | AK34: FALSE
A35: =SUBTOTAL(3,$B$2:B35) -> 34 | B35: SMK | C35: Balikpapan | D35: 69960805 | E35: SMK PERSADA BHAKTI BALIKPAPAN | F35: JL. PRONA II GG.5 RT 24 NO. 99 | G35: 313 | H35: 612775750 | L35: 000.4.3.2/ | M35: 17097 | N35: /Disdikbud-Ib | O35: TRUE | P35: TRUE | Q35: TRUE | R35: TRUE | S35: TRUE | T35: TRUE | U35: TRUE | V35: TRUE | W35: TRUE | X35: TRUE | Y35: BANKALTIMTARA | Z35: 0031576491 | AA35: 69960805 SMK PERSADA BHAKTI BP | AE35: TRUE | AF35: 45870 | AH35: TRUE | AI35: 45946 | AJ35: Perbaikan tanggal SPTJB | AK35: TRUE | AL35: 46002 | AM35: OKE | AX35: TRUE | AY35: =IF(MOD(H35,4)=0,H35/4,ROUNDUP(H35/4,0)) -> 153193938 | BV35: TRUE | BW35: =IF(MOD(H35,4)=0,H35/4,ROUNDDOWN(H35/4,0)) -> 153193937 | CR35: TRUE | CS35: =IF(MOD(H35,4)=0,H35/4,ROUNDUP(H35/4,0)) -> 153193938
A36: =SUBTOTAL(3,$B$2:B36) -> 35 | B36: SMK | C36: Balikpapan | D36: 30407679 | E36: SMK SINAR PANCASILA | F36: JL. TELAGA SARI GN.PASIR | G36: 95 | H36: 185986250 | L36: 000.4.3.2/ | M36: 17098 | N36: /Disdikbud-Ib | O36: TRUE | P36: TRUE | Q36: TRUE | R36: TRUE | S36: TRUE | T36: TRUE | U36: TRUE | V36: TRUE | W36: TRUE | X36: TRUE | Y36: BANKALTIMTARA | Z36: 0031476178 | AA36: SMK SINAR PANCASILA BALIKPAPAN | AE36: TRUE | AF36: 45870 | AH36: TRUE | AI36: 45938 | AJ36: OKE | AK36: TRUE | AL36: 45978 | AM36: OKE | AX36: TRUE | AY36: =IF(MOD(H36,4)=0,H36/4,ROUNDUP(H36/4,0)) -> 46496563 | BT36: TRUE | BU36: =IF(MOD(H36,4)=0,H36/4,ROUNDDOWN(H36/4,0)) -> 46496562 | CJ36: TRUE | CK36: =IF(MOD(H36,4)=0,H36/4,ROUNDUP(H36/4,0)) -> 46496563
A37: =SUBTOTAL(3,$B$2:B37) -> 36 | B37: SMK | C37: Balikpapan | D37: 30407677 | E37: SMKS ADZKIYA | F37: JL. MULAWARMAN KOMPLEK PERUMAHAN RAWA MANGUN INDAH | G37: 421 | H37: 824212750 | L37: 000.4.3.2/ | M37: 17099 | N37: /Disdikbud-Ib | O37: TRUE | P37: TRUE | Q37: TRUE | R37: TRUE | S37: TRUE | T37: TRUE | U37: TRUE | V37: TRUE | W37: TRUE | X37: TRUE | Y37: BANKALTIMTARA | Z37: 0031475961 | AA37: SMK ADZKIYA | AE37: TRUE | AF37: 45870 | AH37: TRUE | AI37: 45938 | AJ37: OKE | AK37: TRUE | AL37: 45978 | AM37: OKE | AX37: TRUE | AY37: =IF(MOD(H37,4)=0,H37/4,ROUNDUP(H37/4,0)) -> 206053188 | BT37: TRUE | BU37: =IF(MOD(H37,4)=0,H37/4,ROUNDDOWN(H37/4,0)) -> 206053187 | CJ37: TRUE | CK37: =IF(MOD(H37,4)=0,H37/4,ROUNDUP(H37/4,0)) -> 206053188
A38: =SUBTOTAL(3,$B$2:B38) -> 37 | B38: SMK | C38: Balikpapan | D38: 30401517 | E38: SMKS AIRLANGGA BALIKPAPAN | F38: JL. S. PARMAN (GN. GUNTUR) NO. 14 | G38: 597 | H38: 1168776750 | L38: 000.4.3.2/ | M38: 17100 | N38: /Disdikbud-Ib | O38: TRUE | P38: TRUE | Q38: TRUE | R38: TRUE | S38: TRUE | T38: TRUE | U38: TRUE | V38: TRUE | W38: TRUE | X38: TRUE | Y38: BANKALTIMTARA | Z38: 0031476372 | AA38: SMK AIRLANGGA BALIKPAPAN | AE38: TRUE | AF38: 45870 | AH38: TRUE | AI38: 45938 | AJ38: OKE | AK38: TRUE | AL38: 45978 | AM38: OKE | AX38: TRUE | AY38: =IF(MOD(H38,4)=0,H38/4,ROUNDUP(H38/4,0)) -> 292194188 | BT38: TRUE | BU38: =IF(MOD(H38,4)=0,H38/4,ROUNDDOWN(H38/4,0)) -> 292194187 | CJ38: TRUE | CK38: =IF(MOD(H38,4)=0,H38/4,ROUNDUP(H38/4,0)) -> 292194188
A39: =SUBTOTAL(3,$B$2:B39) -> 38 | B39: SMK | C39: Balikpapan | D39: 30401515 | E39: SMKS DUTA BANGSA BALIKPAPAN | F39: MULAWARMAN | G39: 203 | H39: 397423250 | L39: 000.4.3.2/ | M39: 17101 | N39: /Disdikbud-Ib | O39: TRUE | P39: TRUE | Q39: TRUE | R39: TRUE | S39: TRUE | T39: TRUE | U39: TRUE | V39: TRUE | W39: TRUE | X39: TRUE | Y39: BANKALTIMTARA | Z39: 1781500158 | AA39: 30401515 SMKS DUTA BANGSA BPP | AE39: TRUE | AF39: 45919 | AG39: Tanggal Surat Pernyataan | AH39: TRUE | AI39: 45953 | AJ39: OKE | AK39: TRUE | AL39: 45996 | AM39: OKE | BB39: TRUE | BC39: =IF(MOD(H39,4)=0,H39/4,ROUNDUP(H39/4,0)) -> 99355813 | BV39: TRUE | BW39: =IF(MOD(H39,4)=0,H39/4,ROUNDDOWN(H39/4,0)) -> 99355812 | CP39: TRUE | CQ39: =IF(MOD(H39,4)=0,H39/4,ROUNDUP(H39/4,0)) -> 99355813
A40: =SUBTOTAL(3,$B$2:B40) -> 39 | B40: SMK | C40: Balikpapan | D40: 30401513 | E40: SMKS IBNU KHALDUN BALIKPAPAN | F40: JLN. SEMOI NO.23 | G40: 577 | H40: 1129621750 | L40: 000.4.3.2/ | M40: 17102 | N40: /Disdikbud-Ib | O40: TRUE | P40: TRUE | Q40: TRUE | R40: TRUE | S40: TRUE | T40: TRUE | U40: TRUE | V40: TRUE | W40: TRUE | X40: TRUE | Y40: BANKALTIMTARA | Z40: 0031476127 | AA40: SMK IBNU KHALDUN BALIKPAPAN | AE40: TRUE | AF40: 45876 | AH40: TRUE | AI40: 45938 | AJ40: OKE | AK40: TRUE | AL40: 45978 | AM40: OKE | AX40: TRUE | AY40: =IF(MOD(H40,4)=0,H40/4,ROUNDUP(H40/4,0)) -> 282405438 | BT40: TRUE | BU40: =IF(MOD(H40,4)=0,H40/4,ROUNDDOWN(H40/4,0)) -> 282405437 | CJ40: TRUE | CK40: =IF(MOD(H40,4)=0,H40/4,ROUNDUP(H40/4,0)) -> 282405438
...

Sheet status rkas
A1: NPSN | B1: Nama Sekolah | C1: Jenis Pendidikan | D1: Jumlah Siswa | E1: Status | F1: Kota/Kabupaten | G1: RKAS | H1: Status RKAS
A2: 69965143 | B2: Sekolah Khusus Santo Fransiskus Assisi | C2: SLB | D2: 81 | E2: Swasta | F2: Kota Balikpapan | G2: BOS Daerah | H2: Anggaran Disetujui
A3: 30407424 | B3: SLB CEMARA WILIS | C3: SLB | D3: 28 | E3: Swasta | F3: Kota Samarinda | G3: BOS Daerah | H3: Anggaran Disetujui
A4: 70043018 | B4: SLB Harapan Insani | C4: SLB | D4: 12 | E4: Swasta | F4: Kab. Kutai Kartanegara | G4: BOS Daerah | H4: Anggaran Disetujui
A5: 30401832 | B5: SLB PERMATA BUNDA | C5: SLB | D5: 33 | E5: Swasta | F5: Kota Bontang | G5: BOS Daerah Revisi Ke 1 | H5: Anggaran Disetujui
A6: 69969001 | B6: SLB Tunas Mandiri | C6: SLB | D6: 47 | E6: Swasta | F6: Kab. Kutai Kartanegara | G6: BOS Daerah | H6: Anggaran Disetujui
A7: 69931888 | B7: SEKOLAH KHUSUS BINA INSAN MANDIRI TENGGARONG | C7: SLB | D7: 44 | E7: Swasta | F7: Kab. Kutai Kartanegara | G7: BOS Daerah | H7: Anggaran Disetujui
A8: 69878226 | B8: SLB BAHASA HATI | C8: SLB | D8: 11 | E8: Swasta | F8: Kab. Kutai Timur | G8: BOS Daerah | H8: Anggaran Disetujui
A9: 70001505 | B9: SLB Bina Kasih Mandiri | C9: SLB | D9: 11 | E9: Swasta | F9: Kota Bontang | G9: BOS Daerah | H9: Anggaran Disetujui
A10: 30405644 | B10: SLB UNTUNG TUAH | C10: SLB | D10: 72 | E10: Swasta | F10: Kota Samarinda | G10: BOS Daerah | H10: Anggaran Disetujui
A11: 69753985 | B11: SLB WIDYA KARYA | C11: SLB | D11: 59 | E11: Swasta | F11: Kota Samarinda | G11: BOS Daerah | H11: Anggaran Disetujui
A12: 69774827 | B12: SLB TUNAS HARAPAN | C12: SLB | D12: 51 | E12: Swasta | F12: Kota Samarinda | G12: BOS Daerah | H12: Anggaran Disetujui
A13: 69889019 | B13: Sekolah Khusus Pelita Bunda | C13: SLB | D13: 48 | E13: Swasta | F13: Kota Samarinda | G13: BOS Daerah | H13: Anggaran Disetujui
... A260: 69830684 | B260: SMK Integral Hidayatullah | C260: SMK | D260: 4 | E260: Swasta | F260: Kota Samarinda | G260: Belum Mengajukan | H260: Belum Mengajukan

Sheet rekap
B3: No | C3: KabKota | D3: SMA | E3: SLB | F3: SMK | G3: MA | H3: TOTAL | J3: SMA | K3: =SUMIF(datadasar!B:B,J3,datadasar!H:H) -> 21320837000
B4: 1 | C4: Balikpapan | D4: =COUNTIFS(datadasar!B:B,$D$3,datadasar!C:C,$C4) -> 17 | E4: =COUNTIFS(datadasar!B:B,$E$3,datadasar!C:C,$C4) -> 3 | F4: =COUNTIFS(datadasar!B:B,$F$3,datadasar!C:C,$C4) -> 25 | G4: =COUNTIFS(datadasar!B:B,$G$3,datadasar!C:C,$C4) -> 8 | H4: =SUM(D4:G4) -> 53 | J4: SMK | K4: =SUMIF(datadasar!B:B,J4,datadasar!H:H) -> 55720349500
B5: 2 | C5: Berau | D5: =COUNTIFS(datadasar!B:B,$D$3,datadasar!C:C,$C5) -> 5 | E5: =COUNTIFS(datadasar!B:B,$E$3,datadasar!C:C,$C5) -> 0 | F5: =COUNTIFS(datadasar!B:B,$F$3,datadasar!C:C,$C5) -> 6 | G5: =COUNTIFS(datadasar!B:B,$G$3,datadasar!C:C,$C5) -> 5 | H5: =SUM(D5:G5) -> 16 | J5: SLB | K5: =SUMIF(datadasar!B:B,J5,datadasar!H:H) -> 2121719000
B6: 3 | C6: Bontang | D6: =COUNTIFS(datadasar!B:B,$D$3,datadasar!C:C,$C6) -> 8 | E6: =COUNTIFS(datadasar!B:B,$E$3,datadasar!C:C,$C6) -> 5 | F6: =COUNTIFS(datadasar!B:B,$F$3,datadasar!C:C,$C6) -> 9 | G6: =COUNTIFS(datadasar!B:B,$G$3,datadasar!C:C,$C6) -> 2 | H6: =SUM(D6:G6) -> 24 | J6: MA | K6: =SUMIF(datadasar!B:B,J6,datadasar!H:H) -> 19650822250
B7: 4 | C7: Kutai Barat | D7: =COUNTIFS(datadasar!B:B,$D$3,datadasar!C:C,$C7) -> 5 | E7: =COUNTIFS(datadasar!B:B,$E$3,datadasar!C:C,$C7) -> 0 | F7: =COUNTIFS(datadasar!B:B,$F$3,datadasar!C:C,$C7) -> 7 | G7: =COUNTIFS(datadasar!B:B,$G$3,datadasar!C:C,$C7) -> 4 | H7: =SUM(D7:G7) -> 16 | K7: =SUM(K3:K6) -> 98813727750
B8: 5 | C8: Kutai Kartanegara | D8: =COUNTIFS(datadasar!B:B,$D$3,datadasar!C:C,$C8) -> 18 | E8: =COUNTIFS(datadasar!B:B,$E$3,datadasar!C:C,$C8) -> 5 | F8: =COUNTIFS(datadasar!B:B,$F$3,datadasar!C:C,$C8) -> 27 | G8: =COUNTIFS(datadasar!B:B,$G$3,datadasar!C:C,$C8) -> 24 | H8: =SUM(D8:G8) -> 74
B9: 6 | C9: Kutai Timur | D9: =COUNTIFS(datadasar!B:B,$D$3,datadasar!C:C,$C9) -> 5 | E9: =COUNTIFS(datadasar!B:B,$E$3,datadasar!C:C,$C9) -> 2 | F9: =COUNTIFS(datadasar!B:B,$F$3,datadasar!C:C,$C9) -> 10 | G9: =COUNTIFS(datadasar!B:B,$G$3,datadasar!C:C,$C9) -> 9 | H9: =SUM(D9:G9) -> 26
B10: 7 | C10: Mahakam Ulu | D10: =COUNTIFS(datadasar!B:B,$D$3,datadasar!C:C,$C10) -> 2 | E10: =COUNTIFS(datadasar!B:B,$E$3,datadasar!C:C,$C10) -> 0 | F10: =COUNTIFS(datadasar!B:B,$F$3,datadasar!C:C,$C10) -> 2 | G10: =COUNTIFS(datadasar!B:B,$G$3,datadasar!C:C,$C10) -> 0 | H10: =SUM(D10:G10) -> 4
B11: 8 | C11: Paser | D11: =COUNTIFS(datadasar!B:B,$D$3,datadasar!C:C,$C11) -> 4 | E11: =COUNTIFS(datadasar!B:B,$E$3,datadasar!C:C,$C11) -> 0 | F11: =COUNTIFS(datadasar!B:B,$F$3,datadasar!C:C,$C11) -> 6 | G11: =COUNTIFS(datadasar!B:B,$G$3,datadasar!C:C,$C11) -> 16 | H11: =SUM(D11:G11) -> 26
B12: 9 | C12: Penajam Paser Utara | D12: =COUNTIFS(datadasar!B:B,$D$3,datadasar!C:C,$C12) -> 3 | E12: =COUNTIFS(datadasar!B:B,$E$3,datadasar!C:C,$C12) -> 0 | F12: =COUNTIFS(datadasar!B:B,$F$3,datadasar!C:C,$C12) -> 5 | G12: =COUNTIFS(datadasar!B:B,$G$3,datadasar!C:C,$C12) -> 7 | H12: =SUM(D12:G12) -> 15
B13: 10 | C13: Samarinda | D13: =COUNTIFS(datadasar!B:B,$D$3,datadasar!C:C,$C13) -> 23 | E13: =COUNTIFS(datadasar!B:B,$E$3,datadasar!C:C,$C13) -> 9 | F13: =COUNTIFS(datadasar!B:B,$F$3,datadasar!C:C,$C13) -> 27 | G13: =COUNTIFS(datadasar!B:B,$G$3,datadasar!C:C,$C13) -> 15 | H13: =SUM(D13:G13) -> 74
B14: TOTAL | D14: =SUM(D4:D13) -> 90 | E14: =SUM(E4:E13) -> 24 | F14: =SUM(F4:F13) -> 124 | G14: =SUM(G4:G13) -> 90 | H14: =SUM(H4:H13) -> 328

Sheet Copy of rekap
B3: No | C3: KabKota | D3: SMA | E3: SLB | F3: SMK | G3: MA | H3: TOTAL | I3: TOTAL PESERTA x3
B4: 1 | C4: Balikpapan | D4: =COUNTIFS(datadasar!B:B,$D$3,datadasar!C:C,$C4) -> 17 | E4: =COUNTIFS(datadasar!B:B,$E$3,datadasar!C:C,$C4) -> 3 | F4: =COUNTIFS(datadasar!B:B,$F$3,datadasar!C:C,$C4) -> 25 | G4: =COUNTIFS(datadasar!B:B,$G$3,datadasar!C:C,$C4) -> 8 | H4: =SUM(D4:G5) -> 68 | I4: =H4*3 -> 204
B5: 2 | C5: Penajam Paser Utara | D5: =COUNTIFS(datadasar!B:B,$D$3,datadasar!C:C,$C5) -> 3 | E5: =COUNTIFS(datadasar!B:B,$E$3,datadasar!C:C,$C5) -> 0 | F5: =COUNTIFS(datadasar!B:B,$F$3,datadasar!C:C,$C5) -> 5 | G5: =COUNTIFS(datadasar!B:B,$G$3,datadasar!C:C,$C5) -> 7
B6: 3 | C6: Kutai Barat | D6: =COUNTIFS(datadasar!B:B,$D$3,datadasar!C:C,$C6) -> 5 | E6: =COUNTIFS(datadasar!B:B,$E$3,datadasar!C:C,$C6) -> 0 | F6: =COUNTIFS(datadasar!B:B,$F$3,datadasar!C:C,$C6) -> 7 | G6: =COUNTIFS(datadasar!B:B,$G$3,datadasar!C:C,$C6) -> 4 | H6: =SUM(D6:G7) -> 20 | I6: =H6*3 -> 60
B7: 4 | C7: Mahakam Ulu | D7: =COUNTIFS(datadasar!B:B,$D$3,datadasar!C:C,$C7) -> 2 | E7: =COUNTIFS(datadasar!B:B,$E$3,datadasar!C:C,$C7) -> 0 | F7: =COUNTIFS(datadasar!B:B,$F$3,datadasar!C:C,$C7) -> 2 | G7: =COUNTIFS(datadasar!B:B,$G$3,datadasar!C:C,$C7) -> 0
B8: 5 | C8: Bontang | D8: =COUNTIFS(datadasar!B:B,$D$3,datadasar!C:C,$C8) -> 8 | E8: =COUNTIFS(datadasar!B:B,$E$3,datadasar!C:C,$C8) -> 5 | F8: =COUNTIFS(datadasar!B:B,$F$3,datadasar!C:C,$C8) -> 9 | G8: =COUNTIFS(datadasar!B:B,$G$3,datadasar!C:C,$C8) -> 2 | H8: =SUM(D8:G9) -> 50 | I8: =H8*3 -> 150
B9: 6 | C9: Kutai Timur | D9: =COUNTIFS(datadasar!B:B,$D$3,datadasar!C:C,$C9) -> 5 | E9: =COUNTIFS(datadasar!B:B,$E$3,datadasar!C:C,$C9) -> 2 | F9: =COUNTIFS(datadasar!B:B,$F$3,datadasar!C:C,$C9) -> 10 | G9: =COUNTIFS(datadasar!B:B,$G$3,datadasar!C:C,$C9) -> 9
B10: 7 | C10: Berau | D10: =COUNTIFS(datadasar!B:B,$D$3,datadasar!C:C,$C10) -> 5 | E10: =COUNTIFS(datadasar!B:B,$E$3,datadasar!C:C,$C10) -> 0 | F10: =COUNTIFS(datadasar!B:B,$F$3,datadasar!C:C,$C10) -> 6 | G10: =COUNTIFS(datadasar!B:B,$G$3,datadasar!C:C,$C10) -> 5 | H10: =SUM(D10:G10) -> 16 | I10: =H10*3 -> 48
B11: 8 | C11: Kutai Kartanegara | D11: =COUNTIFS(datadasar!B:B,$D$3,datadasar!C:C,$C11) -> 18 | E11: =COUNTIFS(datadasar!B:B,$E$3,datadasar!C:C,$C11) -> 5 | F11: =COUNTIFS(datadasar!B:B,$F$3,datadasar!C:C,$C11) -> 27 | G11: =COUNTIFS(datadasar!B:B,$G$3,datadasar!C:C,$C11) -> 24 | H11: =SUM(D11:G11) -> 74 | I11: =H11*3 -> 222
B12: 9 | C12: Paser | D12: =COUNTIFS(datadasar!B:B,$D$3,datadasar!C:C,$C12) -> 4 | E12: =COUNTIFS(datadasar!B:B,$E$3,datadasar!C:C,$C12) -> 0 | F12: =COUNTIFS(datadasar!B:B,$F$3,datadasar!C:C,$C12) -> 6 | G12: =COUNTIFS(datadasar!B:B,$G$3,datadasar!C:C,$C12) -> 16 | H12: =SUM(D12:G12) -> 26 | I12: =H12*3 -> 78
B13: 10 | C13: Samarinda | D13: =COUNTIFS(datadasar!B:B,$D$3,datadasar!C:C,$C13) -> 23 | E13: =COUNTIFS(datadasar!B:B,$E$3,datadasar!C:C,$C13) -> 9 | F13: =COUNTIFS(datadasar!B:B,$F$3,datadasar!C:C,$C13) -> 27 | G13: =COUNTIFS(datadasar!B:B,$G$3,datadasar!C:C,$C13) -> 15 | H13: =SUM(D13:G13) -> 74 | I13: =H13*3 -> 222
B14: TOTAL | D14: =SUM(D4:D13) -> 90 | E14: =SUM(E4:E13) -> 24 | F14: =SUM(F4:F13) -> 124 | G14: =SUM(G4:G13) -> 90 | H14: =SUM(H4:H13) -> 328 | I14: =H14*3 -> 984

Sheet rekap (1)
A2: SMA Swasta | B2: ='[1]SMA-S'!G98 -> #REF!
A3: SMK Swasta | B3: ='[2]SMK-S'!G133 -> #REF!
A4: SLB Swasta | B4: ='[3]SLB-S'!G34 -> #REF!
A5: MA | B5: ='[4]MA (1)'!G102 -> #REF!
B6: =SUM(B2:B5) -> #REF!
B8: =B2+B3+B4+B5 -> #REF!

Sheet Daftar Sekolah
A1: No | B1: NPSN | C1: Nama Sekolah | D1: Kab/Kota | E1: Jumlah Siswa | F1: Jumlah Dana
A2: 1 | B2: 69950015 | C2: SMA Islam Terpadu Granada | D2: Samarinda | E2: 356 | F2: 669280000
A3: 2 | B3: 30404461 | C3: SMAS Islam Samarinda | D3: Samarinda | E3: 313 | F3: 588440000
A4: 3 | B4: 30404179 | C4: SMAS Sunodia Samarinda | D4: Samarinda | E4: 295 | F4: 554600000
A5: 4 | B5: 69991845 | C5: SMA IT TURSINA | D5: Samarinda | E5: 27 | F5: 50760000
A6: 5 | B6: 30404269 | C6: SMAS Nabil Husein Samarinda | D6: Samarinda | E6: 155 | F6: 291400000
A7: 6 | B7: 30403013 | C7: SMAS Syaichona Cholil Samarinda | D7: Samarinda | E7: 247 | F7: 464360000
A8: 7 | B8: 30404270 | C8: SMAS Setia Marga Samarinda | D8: Samarinda | E8: 245 | F8: 460600000
A9: 8 | B9: 30404266 | C9: SMAS Muhammadiyah 2 Samarinda | D9: Samarinda | E9: 42 | F9: 78960000
A10: 9 | B10: 69948500 | C10: SMA Budi Luhur | D10: Samarinda | E10: 264 | F10: 496320000
A11: 10 | B11: 69774826 | C11: SMAS Plus Melati | D11: Samarinda | E11: 96 | F11: 180480000
A12: 11 | B12: 30401063 | C12: SMAS Katolik W. R. Soepratman | D12: Samarinda | E12: 338 | F12: 635440000
A13: 12 | B13: 30404265 | C13: SMAS Ma arif Samarinda | D13: Samarinda | E13: 51 | F13: 95880000
... A328: 92 | B328: 131164030001 | C328: MAN BERAU | D328: Berau | E328: 391 | F328: 938400000
